17-01-2023 15:47:01 - www.osteopatafrancescogatto.it - ERROR - check_MD - 167 - Exception occurred
Traceback (most recent call last):
  File "C:\Users\Utente\AppData\Local\Programs\Python\Python311\Lib\site-packages\urllib3\response.py", line 761, in _update_chunk_length
    self.chunk_left = int(line, 16)
                      ^^^^^^^^^^^^^
ValueError: invalid literal for int() with base 16: b''

During handling of the above exception, another exception occurred:

Traceback (most recent call last):
  File "C:\Users\Utente\AppData\Local\Programs\Python\Python311\Lib\site-packages\urllib3\response.py", line 444, in _error_catcher
    yield
  File "C:\Users\Utente\AppData\Local\Programs\Python\Python311\Lib\site-packages\urllib3\response.py", line 828, in read_chunked
    self._update_chunk_length()
  File "C:\Users\Utente\AppData\Local\Programs\Python\Python311\Lib\site-packages\urllib3\response.py", line 765, in _update_chunk_length
    raise InvalidChunkLength(self, line)
urllib3.exceptions.InvalidChunkLength: InvalidChunkLength(got length b'', 0 bytes read)

During handling of the above exception, another exception occurred:

Traceback (most recent call last):
  File "C:\Users\Utente\AppData\Local\Programs\Python\Python311\Lib\site-packages\requests\models.py", line 816, in generate
    yield from self.raw.stream(chunk_size, decode_content=True)
  File "C:\Users\Utente\AppData\Local\Programs\Python\Python311\Lib\site-packages\urllib3\response.py", line 624, in stream
    for line in self.read_chunked(amt, decode_content=decode_content):
  File "C:\Users\Utente\AppData\Local\Programs\Python\Python311\Lib\site-packages\urllib3\response.py", line 816, in read_chunked
    with self._error_catcher():
  File "C:\Users\Utente\AppData\Local\Programs\Python\Python311\Lib\contextlib.py", line 155, in __exit__
    self.gen.throw(typ, value, traceback)
  File "C:\Users\Utente\AppData\Local\Programs\Python\Python311\Lib\site-packages\urllib3\response.py", line 461, in _error_catcher
    raise ProtocolError("Connection broken: %r" % e, e)
urllib3.exceptions.ProtocolError: ("Connection broken: InvalidChunkLength(got length b'', 0 bytes read)", InvalidChunkLength(got length b'', 0 bytes read))

During handling of the above exception, another exception occurred:

Traceback (most recent call last):
  File "C:\Users\Utente\Desktop\Visibility\CheckWidget\WidgetChecker.py", line 156, in check_MD
    self.outcome.allows_booking = MappingIndividual(url = self.md[0]['href']).mapping.value
                                  ^^^^^^^^^^^^^^^^^^^^^^^^^^^^^^^^^^^^^^^^^^^
  File "C:\Users\Utente\Desktop\Visibility\CheckWidget\MappingMD.py", line 53, in __init__
    super().__init__(url, profile_type = ProfileType.INDIVIDUAL)
  File "C:\Users\Utente\Desktop\Visibility\CheckWidget\MappingMD.py", line 29, in __init__
    self.r = requests.get(url= self.url_md, headers=headers_md)
             ^^^^^^^^^^^^^^^^^^^^^^^^^^^^^^^^^^^^^^^^^^^^^^^^^^
  File "C:\Users\Utente\AppData\Local\Programs\Python\Python311\Lib\site-packages\requests\api.py", line 73, in get
    return request("get", url, params=params, **kwargs)
           ^^^^^^^^^^^^^^^^^^^^^^^^^^^^^^^^^^^^^^^^^^^^
  File "C:\Users\Utente\AppData\Local\Programs\Python\Python311\Lib\site-packages\requests\api.py", line 59, in request
    return session.request(method=method, url=url, **kwargs)
           ^^^^^^^^^^^^^^^^^^^^^^^^^^^^^^^^^^^^^^^^^^^^^^^^^
  File "C:\Users\Utente\AppData\Local\Programs\Python\Python311\Lib\site-packages\requests\sessions.py", line 587, in request
    resp = self.send(prep, **send_kwargs)
           ^^^^^^^^^^^^^^^^^^^^^^^^^^^^^^
  File "C:\Users\Utente\AppData\Local\Programs\Python\Python311\Lib\site-packages\requests\sessions.py", line 723, in send
    history = [resp for resp in gen]
              ^^^^^^^^^^^^^^^^^^^^^^
  File "C:\Users\Utente\AppData\Local\Programs\Python\Python311\Lib\site-packages\requests\sessions.py", line 723, in <listcomp>
    history = [resp for resp in gen]
              ^^^^^^^^^^^^^^^^^^^^^^
  File "C:\Users\Utente\AppData\Local\Programs\Python\Python311\Lib\site-packages\requests\sessions.py", line 266, in resolve_redirects
    resp = self.send(
           ^^^^^^^^^^
  File "C:\Users\Utente\AppData\Local\Programs\Python\Python311\Lib\site-packages\requests\sessions.py", line 745, in send
    r.content
  File "C:\Users\Utente\AppData\Local\Programs\Python\Python311\Lib\site-packages\requests\models.py", line 899, in content
    self._content = b"".join(self.iter_content(CONTENT_CHUNK_SIZE)) or b""
                    ^^^^^^^^^^^^^^^^^^^^^^^^^^^^^^^^^^^^^^^^^^^^^^^
  File "C:\Users\Utente\AppData\Local\Programs\Python\Python311\Lib\site-packages\requests\models.py", line 818, in generate
    raise ChunkedEncodingError(e)
requests.exceptions.ChunkedEncodingError: ("Connection broken: InvalidChunkLength(got length b'', 0 bytes read)", InvalidChunkLength(got length b'', 0 bytes read))
